<mujoco model="centipede">
  <compiler angle="degree" coordinate="local" inertiafromgeom="true"/>
  <option integrator="RK4" timestep="0.01"/>
  <custom>
    <numeric data="0.0 0.0 0.75 0.0 0.0 0.0 0.0 0.0 1.0 0.0 1.0 0.0 0.0 0.0 1.0 0.0 1.0 0.0 0.0 0.0 1.0 0.0 1.0" name="init_qpos"/>
  </custom>
  <default>
    <joint armature="1" damping="1" limited="true"/>
    <geom conaffinity="0" condim="3" density="50.0" friction="1 0.5 0.5" margin="0.01" rgba="0.8 0.6 0.4 1"/>
  </default>
  <asset>
    <texture builtin="gradient" height="100" rgb1="1 1 1" rgb2="0 0 0" type="skybox" width="100"/>
    <texture builtin="flat" height="1278" mark="cross" markrgb="1 1 1" name="texgeom" random="0.01" rgb1="0.8 0.6 0.4" rgb2="0.8 0.6 0.4" type="cube" width="127"/>
    <texture builtin="checker" height="100" name="texplane" rgb1="0 0 0" rgb2="0.8 0.8 0.8" type="2d" width="100" mark="edge" markrgb=".2 .5 .3"/>
    <material name="MatPlane" reflectance="0.5" shininess="1" specular="1" texrepeat="400 400" texture="texplane"/>
    <material name="geom" texture="texgeom" texuniform="true"/>
  </asset>
  <worldbody>
    <light cutoff="100" diffuse="1 1 1" dir="-0 0 -1" directional="true" exponent="1" pos="0 0 1.3" specular=".1 .1 .1" mode="trackcom"/>
    <geom conaffinity="1" condim="3" material="MatPlane" name="floor" pos="0 0 0" rgba="0.8 0.9 0.8 1" size="600 600 40" type="plane"/>
    
    <body name="torso" pos="0 0 0.75">
      <camera name="track" mode="trackcom" pos="0 -3 0.3" xyaxes="1 0 0 0 0 1"/>
      <geom name="torso_geom" pos="0 0 0" size="0.25" type="sphere" rgba='1 0 0 1'/>
      <joint armature="0" damping="0" limited="false" margin="0.01" name="root" pos="0 0 0" type="free"/>
      
      <!-- Left Leg (y positive) -->
      <body name="left_leg_0" pos="0 0 0">
         <geom fromto="0.0 0.0 0.0 0.0 0.28 0.0" name="aux_left_0_geom" size="0.08" type="capsule" />
         <body name="aux_left_0" pos="0.0 0.28 0">
             <joint axis="0 0 1" name="hip_left_0" pos="0.0 0.0 0.0" range="-30 30" type="hinge"/> 
             <geom fromto="0.0 0.0 0.0 0.0 0.28 0.0" name="left_leg_0_geom" size="0.08" type="capsule" />
             <body pos="0.0 0.28 0">
                 <joint axis="-1 0 0" name="ankle_left_0" pos="0.0 0.0 0.0" range="30 70" type="hinge"/>
                 <geom fromto="0.0 0.0 0.0 0.0 0.5 0.0" name="left_ankle_0_geom" size="0.08" type="capsule" />
             </body>
         </body>
      </body>


      <!-- Right Leg (y negative) -->
      <body name="right_leg_0" pos="0 0 0">
         <geom fromto="0.0 0.0 0.0 0.0 -0.28 0.0" name="aux_right_0_geom" size="0.08" type="capsule" />
         <body name="aux_right_0" pos="0.0 -0.28 0">
             <joint axis="0 0 -1" name="hip_right_0" pos="0.0 0.0 0.0" range="-30 30" type="hinge"/>
             <geom fromto="0.0 0.0 0.0 0.0 -0.28 0.0" name="right_leg_0_geom" size="0.08" type="capsule" />
             <body pos="0.0 -0.28 0">
                 <joint axis="1 0 0" name="ankle_right_0" pos="0.0 0.0 0.0" range="30 70" type="hinge"/>
                 <geom fromto="0.0 0.0 0.0 0.0 -0.5 0.0" name="right_ankle_0_geom" size="0.08" type="capsule" />
             </body>
         </body>
      </body>
      
      <!-- Torso 1 (Behind, -X) -->
      <body name="torso_1" pos="-0.5 0 0">
       <joint axis="0 0 1" name="connector_rl_1" pos="0.3 0 0" range="-20 20" type="hinge"/>
       <joint axis="0 1 0" name="connector_ud_1" pos="0.3 0 0" range="-20 20" type="hinge"/>
       
       <geom name="torso_1_geom" pos="0 0 0" size="0.25" type="sphere"/>
       

       <!-- Left Leg 1 -->
      <body name="left_leg_1" pos="0 0 0">
         <geom fromto="0.0 0.0 0.0 -0.0 0.28 0.0" name="aux_left_1_geom" size="0.08" type="capsule" />
         <body name="aux_left_1" pos="-0.0 0.28 0">
             <joint axis="0 0 1" name="hip_left_1" pos="0.0 0.0 0.0" range="-30 30" type="hinge"/>
             <geom fromto="0.0 0.0 0.0 -0.0 0.28 0.0" name="left_leg_1_geom" size="0.08" type="capsule" />
             <body pos="0.0 0.28 0">
                 <joint axis="-1 0 0" name="ankle_left_1" pos="0.0 0.0 0.0" range="30 70" type="hinge"/>
                 <geom fromto="0.0 0.0 0.0 0.0 0.5 0.0" name="left_ankle_1_geom" size="0.08" type="capsule" />
             </body>
         </body>
      </body>
             <!-- Right Leg 1 -->
      <body name="right_leg_1" pos="0 0 0">
         <geom fromto="0.0 0.0 0.0 -0.0 -0.28 0.0" name="aux_right_1_geom" size="0.08" type="capsule" />
         <body name="aux_right_1" pos="-0.0 -0.28 0">
             <joint axis="0 0 -1" name="hip_right_1" pos="0.0 0.0 0.0" range="-30 30" type="hinge"/>
             <geom fromto="0.0 0.0 0.0 -0.0 -0.28 0.0" name="right_leg_1_geom" size="0.08" type="capsule" />
             <body pos="0.0 -0.28 0">
                 <joint axis="1 0 0" name="ankle_right_1" pos="0.0 0.0 0.0" range="30 70" type="hinge"/>
                 <geom fromto="0.0 0.0 0.0 0.0 -0.5 0.0" name="right_ankle_1_geom" size="0.08" type="capsule" />
             </body>
         </body>
      </body>
      </body>
      
    </body>
  </worldbody>
  <actuator>
      <!-- Motors -->
      <!-- Legs 0 -->
      <motor name="hip_left_0" ctrllimited="true" ctrlrange="-1.0 1.0" joint="hip_left_0" gear="75"/>
      <motor name="ankle_left_0" ctrllimited="true" ctrlrange="-1.0 1.0" joint="ankle_left_0" gear="75"/>      
      <motor name="hip_right_0" ctrllimited="true" ctrlrange="-1.0 1.0" joint="hip_right_0" gear="75"/>
      <motor name="ankle_right_0" ctrllimited="true" ctrlrange="-1.0 1.0" joint="ankle_right_0" gear="75"/>  

      <!-- Torso 1 Joints -->
      <motor name="connector_rl_1" ctrllimited="true" ctrlrange="-1.0 1.0" joint="connector_rl_1" gear="50"/>
      <motor name="connector_ud_1" ctrllimited="true" ctrlrange="-1.0 1.0" joint="connector_ud_1" gear="50"/>
      
       <!-- Legs 1 -->
      <motor name="hip_left_1" ctrllimited="true" ctrlrange="-1.0 1.0" joint="hip_left_1" gear="75"/>
      <motor name="ankle_left_1" ctrllimited="true" ctrlrange="-1.0 1.0" joint="ankle_left_1" gear="75"/>       
      <motor name="hip_right_1" ctrllimited="true" ctrlrange="-1.0 1.0" joint="hip_right_1" gear="75"/>
      <motor name="ankle_right_1" ctrllimited="true" ctrlrange="-1.0 1.0" joint="ankle_right_1" gear="75"/>
  </actuator>
</mujoco>